Workbook
Name AnFixcost: '36-Mo-Fin-Pr'!$B$61:$D$70
Name PrFFY1: '36-Mo-Fin-Pr'!$C$75:$Q$148
Name PrFFY2: '36-Mo-Fin-Pr'!$C$155:$Q$228
Name PrFFY3: '36-Mo-Fin-Pr'!$C$235:$Q$308

Sheet Assumptions
B1: ASSUMPTIONS
B3: Income Statement | C3: Table Used | D3: Description
A4: 1.1 | B4: Depreciation Expense | C4: 1. Pro-forma Income Statement | D4: Depreciation expense is estimated based on the cost of the equipment. The values for the assumed growth rates are : FY-1 = 1.00; FY-2 = 1.11; FY-3 = 1.20
C5: 2. Pro-Forma Statement of Cash Flows
C6: 3. Business Financial Statement
A7: 1.2 | B7: Insurance | C7: 1. Pro-forma Income Statement | D7: The amount of insurance that was incurred/used up/expired during the period of time, The amount will vary for each individual project and will be based on the terms of the insurance contracts. The values for the assumed growth rates are : FY-1 = 1.00; FY-2 = 1.11; FY-3 = 1.20
C8: 2. Pro-Forma Statement of Cash Flows
C9: 3. Business Financial Statement
A10: 1.3 | B10: Tax Rate | C10: 1. Pro-forma Income Statement | D10: The value of the tax rate is imported from the main simulation
C11: 2. Business Financial Statement
B12: Cash Flow
A13: 2.1 | B13: Beginning Cash flow | C13: 1. Pro-Forma Statement of Cash Flows | D13: Beginning cash flow is zero in the beginning of FY-1 (for FY-2 and FY-3 the ending cashflows of the previous years have been used)
C14: 2. Business Financial Statement
A15: 2.2 | B15: Insurance | C15: 1. Pro-forma Income Statement | D15: Insurance expense shall be estimated based on the country and the market in which a student is planning to operate his/her business. Evaluating current insurance premiums in respective countries/ regions is crucial for the estimation of insurance expense.
C16: 2. Pro-Forma Statement of Cash Flows
C17: 3. Business Financial Statement
A18: 2.6 | B18: Add back depreciation | C18: 1. Pro-Forma Statement of Cash Flows | D18: The depreciaton is added back to the cash flow as it is a non-cash item.

Sheet 36-Mo-Fin-Pr
A1: 1 | B1: Sales Projections
D2: Sales Projections: Products sold per month (for FY-1, FY-2, and FY-3)
B4: Products | D4: Jan | E4: Feb | F4: Mar | G4: Apr | H4: May | I4: Jun | J4: Jul | K4: Aug | L4: Sep | M4: Oct | N4: Nov | O4: Dec | P4: Overall
B6: BR01-01, | C6: FY-1 | D6: 1206.6368 | E6: 1206.6368 | F6: 1310.0292 | G6: 1389.3976 | H6: 1588.631 | I6: 1852.5301 | J6: 1852.5301 | K6: 1985.7888 | L6: 1985.7888 | M6: 1927.3538 | N6: 1389.3976 | O6: 1389.3976 | P6: 19084.118 | Q6: FY-1
C7: FY-2 | D7: 1509.7736 | E7: 1509.7736 | F7: 1568.9735 | G7: 1390.8605 | H7: 1622.6706 | I7: 2086.2908 | J7: 2086.2908 | K7: 2193.2619 | L7: 2193.2619 | M7: 2143.798 | N7: 1390.8605 | O7: 1390.8605 | P7: 21086.676 | Q7: FY-2
C8: FY-3 | D8: 1441.9646 | E8: 1441.9646 | F8: 1500.1127 | G8: 1544.6035 | H8: 1765.2611 | I8: 2206.5764 | J8: 2206.5764 | K8: 2274.0199 | L8: 2274.0199 | M8: 2242.8597 | N8: 1544.6035 | O8: 1544.6035 | P8: 21987.166 | Q8: FY-3
B9: BR01-02, | C9: FY-1 | D9: 1220.3175 | E9: 1220.3175 | F9: 1261.7068 | G9: 1471.9912 | H9: 1682.2757 | I9: 2102.8446 | J9: 2102.8446 | K9: 2346.2869 | L9: 2346.2869 | M9: 2313.1291 | N9: 1471.9912 | O9: 1431.5304 | P9: 20971.522 | Q9: FY-1
C10: FY-2 | D10: 1216.3831 | E10: 1216.3831 | F10: 1257.5015 | G10: 1467.085 | H10: 1676.6686 | I10: 2095.8358 | J10: 2095.8358 | K10: 2338.3549 | L10: 2338.3549 | M10: 2305.4193 | N10: 1467.085 | O10: 1467.085 | P10: 20941.992 | Q10: FY-2
C11: FY-3 | D11: 1233.9239 | E11: 1233.9239 | F11: 1276.2573 | G11: 1488.9669 | H11: 1701.6764 | I11: 2127.0955 | J11: 2127.0955 | K11: 2373.7376 | L11: 2373.7376 | M11: 2339.8051 | N11: 1488.9669 | O11: 1488.9669 | P11: 21254.153 | Q11: FY-3
B12: BR01-03, | C12: FY-1 | D12: 0 | E12: 0 | F12: 0 | G12: 0 | H12: 0 | I12: 1208.741 | J12: 1208.741 | K12: 1240 | L12: 1240 | M12: 1240 | N12: 0 | O12: 0 | P12: 6137.482 | Q12: FY-1
C13: FY-2 | D13: 0 | E13: 0 | F13: 0 | G13: 0 | H13: 1045.9823 | I13: 1240 | J13: 1240 | K13: 1240 | L13: 1240 | M13: 1240 | N13: 0 | O13: 0 | P13: 7245.9823 | Q13: FY-2
C14: FY-3 | D14: 0 | E14: 0 | F14: 0 | G14: 1086.7349 | H14: 1240 | I14: 1240 | J14: 1240 | K14: 1240 | L14: 1240 | M14: 1240 | N14: 1086.7349 | O14: 1086.7349 | P14: 10700.205 | Q14: FY-3
B15: BR01-04, | C15: FY-1 | D15: 0 | E15: 0 | F15: 0 | G15: 0 | H15: 0 | I15: 1036.0637 | J15: 1036.0637 | K15: 1240 | L15: 1240 | M15: 1139.6701 | N15: 0 | O15: 0 | P15: 5691.7975 | Q15: FY-1
C16: FY-2 | D16: 0 | E16: 0 | F16: 0 | G16: 0 | H16: 0 | I16: 1214.0866 | J16: 1214.0866 | K16: 1240 | L16: 1240 | M16: 1240 | N16: 0 | O16: 0 | P16: 6148.1732 | Q16: FY-2
C17: FY-3 | D17: 0 | E17: 0 | F17: 0 | G17: 0 | H17: 1076.385 | I17: 1240 | J17: 1240 | K17: 1240 | L17: 1240 | M17: 1240 | N17: 0 | O17: 0 | P17: 7276.385 | Q17: FY-3
B18: BR01-05, | C18: FY-1 | D18: 0 | E18: 0 | F18: 0 | G18: 0 | H18: 0 | I18: 1036.0637 | J18: 1036.0637 | K18: 1240 | L18: 1240 | M18: 1139.6701 | N18: 0 | O18: 0 | P18: 5691.7975 | Q18: FY-1
C19: FY-2 | D19: 0 | E19: 0 | F19: 0 | G19: 0 | H19: 0 | I19: 1214.0866 | J19: 1214.0866 | K19: 1240 | L19: 1240 | M19: 1240 | N19: 0 | O19: 0 | P19: 6148.1732 | Q19: FY-2
C20: FY-3 | D20: 0 | E20: 0 | F20: 0 | G20: 0 | H20: 1076.385 | I20: 1240 | J20: 1240 | K20: 1240 | L20: 1240 | M20: 1240 | N20: 0 | O20: 0 | P20: 7276.385 | Q20: FY-3
B21: BR01-06, | C21: FY-1 | D21: 0 | E21: 0 | F21: 0 | G21: 0 | H21: 0 | I21: 1208.741 | J21: 1208.741 | K21: 1240 | L21: 1240 | M21: 1240 | N21: 0 | O21: 0 | P21: 6137.482 | Q21: FY-1
C22: FY-2 | D22: 0 | E22: 0 | F22: 0 | G22: 0 | H22: 0 | I22: 1214.0866 | J22: 1214.0866 | K22: 1240 | L22: 1240 | M22: 1240 | N22: 0 | O22: 0 | P22: 6148.1732 | Q22: FY-2
C23: FY-3 | D23: 0 | E23: 0 | F23: 0 | G23: 1014.2859 | H23: 1159.1839 | I23: 1240 | J23: 1240 | K23: 1240 | L23: 1240 | M23: 1240 | N23: 1014.2859 | O23: 1014.2859 | P23: 10402.042 | Q23: FY-3
B24: BR01-07, | C24: FY-1 | D24: 3753.3632 | E24: 3753.3632 | F24: 4889.9708 | G24: 6050.6024 | H24: 6918.2319 | I24: 8067.4699 | J24: 8067.4699 | K24: 10377.348 | L24: 10377.348 | M24: 9232.6462 | N24: 6050.6024 | O24: 6050.6024 | P24: 83589.018 | Q24: FY-1
C25: FY-2 | D25: 4690.2264 | E25: 4690.2264 | F25: 5848.9624 | G25: 6049.1395 | H25: 7057.3294 | I25: 9073.7092 | J25: 9073.7092 | K25: 11446.738 | L25: 11446.738 | M25: 10256.202 | N25: 6049.1395 | O25: 6049.1395 | P25: 91731.26 | Q25: FY-2
C26: FY-3 | D26: 4758.0354 | E26: 4758.0354 | F26: 5939.8873 | G26: 7135.3965 | H26: 8154.7389 | I26: 10193.424 | J26: 10193.424 | K26: 12605.98 | L26: 12605.98 | M26: 11397.14 | N26: 7135.3965 | O26: 7135.3965 | P26: 102012.83 | Q26: FY-3
B27: BR01-08, | C27: FY-1 | D27: 4979.6825 | E27: 4979.6825 | F27: 6178.2932 | G27: 7208.0088 | H27: 8237.7243 | I27: 10297.155 | J27: 10297.155 | K27: 12533.713 | L27: 12533.713 | M27: 11326.871 | N27: 7208.0088 | O27: 6008.4696 | P27: 101788.48 | Q27: FY-1
C28: FY-2 | D28: 4983.6169 | E28: 4983.6169 | F28: 6182.4985 | G28: 7212.915 | H28: 8243.3314 | I28: 10304.164 | J28: 10304.164 | K28: 12541.645 | L28: 12541.645 | M28: 11334.581 | N28: 7212.915 | O28: 7212.915 | P28: 103058.01 | Q28: FY-2
C29: FY-3 | D29: 4966.0761 | E29: 4966.0761 | F29: 6163.7427 | G29: 7191.0331 | H29: 8218.3236 | I29: 10272.904 | J29: 10272.904 | K29: 12506.262 | L29: 12506.262 | M29: 11300.195 | N29: 7191.0331 | O29: 7191.0331 | P29: 102745.85 | Q29: FY-3
B30: BR01-09, | C30: FY-1 | D30: 0 | E30: 470.39059 | F30: 0 | G30: 0 | H30: 173.13711 | I30: 470.39059 | J30: 470.39059 | K30: 36.863418 | L30: 36.863418 | M30: 200.65984 | N30: 0 | O30: 0 | P30: 1858.6956 | Q30: FY-1
C31: FY-2 | D31: 0 | E31: 0 | F31: 22.064145 | G31: 0 | H31: 194.01768 | I31: 77.740129 | J31: 77.740129 | K31: 0 | L31: 0 | M31: 0 | N31: 0 | O31: 0 | P31: 371.56208 | Q31: FY-2
C32: FY-3 | D32: 0 | E32: 0 | F32: 0 | G32: 378.97923 | H32: 408.04608 | I32: 0 | J32: 0 | K32: 0 | L32: 0 | M32: 0 | N32: 378.97923 | O32: 378.97923 | P32: 1544.9838 | Q32: FY-3
B34: Total Products | C34: FY-1 | D34: 11160 | E34: 11630.391 | F34: 13640 | G34: 16120 | H34: 18600 | I34: 27280 | J34: 27280 | K34: 32240 | L34: 32240 | M34: 29760 | N34: 16120 | O34: 14880 | P34: 250950.39 | Q34: FY-1
B35: per Months | C35: FY-2 | D35: 12400 | E35: 12400 | F35: 14880 | G35: 16120 | H35: 19840 | I35: 28520 | J35: 28520 | K35: 33480 | L35: 33480 | M35: 31000 | N35: 16120 | O35: 16120 | P35: 262880 | Q35: FY-2
C36: FY-3 | D36: 12400 | E36: 12400 | F36: 14880 | G36: 19840 | H36: 24800 | I36: 29760 | J36: 29760 | K36: 34720 | L36: 34720 | M36: 32240 | N36: 19840 | O36: 19840 | P36: 285200 | Q36: FY-3
P37: 799030.39 | Q37: Overall
A41: 2 | B41: Prices and Variable Costs per product
E44: Variable Costs per Unit
B45: Product ID | C45: Distribution | D45: Name | E45: Materials | F45: Labor | G45: Others | H45: Overall | I45: Prices
B46: BR01-01, | C46: [retail] | D46: Pilsner | E46: 0.56 | F46: 0.3 | G46: 0.3 | H46: 1.16 | I46: 4
B47: BR01-02, | C47: [retail] | D47: Bavarian Lager | E47: 0.5 | F47: 0.3 | G47: 0.3 | H47: 1.1 | I47: 4
B48: BR01-03, | C48: [retail] | D48: Light Wheat | E48: 0.5 | F48: 0.3 | G48: 0.3 | H48: 1.1 | I48: 3.5
...

Sheet Pro-Forma Income statement
A1: PRO-FORMA INCOME STATEMENT
B3: FY-1 | C3: FY-2 | D3: FY-3
A4: Earning (Profit) Before Taxes | B4: =VLOOKUP("Profit (Before Taxes)",PrFFY1,14,FALSE) -> -24805.884 | C4: =VLOOKUP("Profit (Before Taxes)",PrFFY2,14,FALSE) -> -19636.348 | D4: =VLOOKUP("Profit (Before Taxes)",PrFFY3,14,FALSE) -> 11217.757
A5: Tax (%) | B5: =VLOOKUP("Profit Taxes",PrFFY1,2,FALSE) -> 0.35 | C5: =VLOOKUP("Profit Taxes",PrFFY2,2,FALSE) -> 0.35 | D5: =VLOOKUP("Profit Taxes",PrFFY3,2,FALSE) -> 0.35
A6: Tax Expense | B6: =VLOOKUP("Profit (Before Taxes)",PrFFY1,14,FALSE)-VLOOKUP("Profit (After Taxes)",PrFFY1,14,FALSE) -> -625 | C6: =VLOOKUP("Profit (Before Taxes)",PrFFY2,14,FALSE)-VLOOKUP("Profit (After Taxes)",PrFFY2,14,FALSE) -> -1187.4997 | D6: =VLOOKUP("Profit (Before Taxes)",PrFFY3,14,FALSE)-VLOOKUP("Profit (After Taxes)",PrFFY3,14,FALSE) -> 5053.833
A7: Net Income (Profit After Taxes) | B7: =B4-B6 -> -24180.884 | C7: =C4-C6 -> -18448.848 | D7: =D4-D6 -> 6163.924
A9: PRO FORMA INCOME PROJECTION | B9: FY-1 | C9: FY-2 | D9: FY-3 | E9: Total 3 Years
A10: Revenue | B10: =VLOOKUP("Total Revenue",PrFFY1,14,FALSE) -> 480126.41 | C10: =VLOOKUP("Total Revenue",PrFFY2,14,FALSE) -> 505074.21 | D10: =VLOOKUP("Total Revenue",PrFFY3,14,FALSE) -> 558719.79 | E10: =B10+C10+D10 -> 1543920.4
A11: Expenses (Variable Costs) | B11: =VLOOKUP("Total Expenses",PrFFY1,14,FALSE) -> 271693.18 | C11: =VLOOKUP("Total Expenses",PrFFY2,14,FALSE) -> 284721.44 | D11: =VLOOKUP("Total Expenses",PrFFY3,14,FALSE) -> 308937.91 | E11: =B11+C11+D11 -> 865352.53
A12: Gross Profit Margin (contribution) | B12: =B10-B11 -> 208433.23 | C12: =C10-C11 -> 220352.77 | D12: =D10-D11 -> 249781.88 | E12: =B12+C12+D12 -> 678567.88
A13: Fixed Costs
A14: a. Rent | B14: =VLOOKUP("Rent",PrFFY1,14,FALSE) -> 5000 | C14: =VLOOKUP("Rent",PrFFY2,14,FALSE) -> 5000 | D14: =VLOOKUP("Rent",PrFFY3,14,FALSE) -> 5000 | E14: =B14+C14+D14 -> 15000
A15: b. Employees salaries | B15: =VLOOKUP("Employees Salaries",PrFFY1,14,FALSE) -> 130000 | C15: =VLOOKUP("Employees Salaries",PrFFY2,14,FALSE) -> 130000 | D15: =VLOOKUP("Employees Salaries",PrFFY3,14,FALSE) -> 130000 | E15: =B15+C15+D15 -> 390000
A16: c. Utilities&Other | B16: =VLOOKUP("Utilities&Other",PrFFY1,14,FALSE) -> 33500 | C16: =VLOOKUP("Utilities&Other",PrFFY2,14,FALSE) -> 33500 | D16: =VLOOKUP("Utilities&Other",PrFFY3,14,FALSE) -> 33500 | E16: =B16+C16+D16 -> 100500
A17: d. Marketing Costs | B17: =VLOOKUP("Marketing Costs",PrFFY1,14,FALSE) -> 38000 | C17: =VLOOKUP("Marketing Costs",PrFFY2,14,FALSE) -> 38000 | D17: =VLOOKUP("Marketing Costs",PrFFY3,14,FALSE) -> 38000 | E17: =B17+C17+D17 -> 114000
A18: e. Loans Payments | B18: =VLOOKUP("Loan Payments",PrFFY1,14,FALSE) -> 19239.119 | C18: =VLOOKUP("Loan Payments",PrFFY2,14,FALSE) -> 19239.119 | D18: =VLOOKUP("Loan Payments",PrFFY3,14,FALSE) -> 19239.119 | E18: =B18+C18+D18 -> 57717.358
A19: f. Depreciation | B19: =VLOOKUP("Depreciation",PrFFY1,14,0) -> 7500 | C19: =VLOOKUP("Depreciation",PrFFY2,14,0) -> 14250 | D19: =VLOOKUP("Depreciation",PrFFY3,14,0) -> 12825 | E19: =B19+C19+D19 -> 34575
A20: Total Fixed Costs | B20: =SUM(B14:B19) -> 233239.12 | C20: =SUM(C14:C19) -> 239989.12 | D20: =SUM(D14:D19) -> 238564.12 | E20: =B20+C20+D20 -> 711792.36
A21: =Total Operating Expenses
A22: Total Expenses (= Direct + Oper Exp) | B22: =B20+B11 -> 504932.3 | C22: =C20+C11 -> 524710.56 | D22: =D20+D11 -> 547502.03 | E22: =E20+E11 -> 1577144.9
A23: Net Income From Operations | B23: =B12-B20 -> -24805.884 | C23: =C12-C20 -> -19636.348 | D23: =D12-D20 -> 11217.757 | E23: =B23+C23+D23 -> -33224.475
A24: = Income Profit (Loss) Before Taxes
A25: Taxes (Profit) | B25: =B5 -> 0.35 | C25: =C5 -> 0.35 | D25: =D5 -> 0.35 | E25: =SUM(B25:D25)/3 -> 0.35
A26: Tax Expense | B26: =B6 -> -625 | C26: =C6 -> -1187.4997 | D26: =D6 -> 5053.833 | E26: =B26+C26+D26 -> 3241.3332
A27: Net Income After Tax | B27: =B23-B26 -> -24180.884 | C27: =C23-C26 -> -18448.848 | D27: =D23-D26 -> 6163.924 | E27: =B27+C27+D27 -> -36465.808
A29: Note: Different methods for depreciation/ ammortization shall be chosen given different nature of fixed and intangible assets. Students shall be able to identify and justify methods that they choose.
A32: Note: Insurance expense shall be estimated based on the country and the market in which a student is planning to operate his/her business. Evaluating current insurance premiums in respective countries/ regions is crucial for the estimation of insurance expense.

Sheet Pro-Forma CF
B1: PRO-FORMA CASH FLOW STATEMENT
B2: PRO FORMA CASH FLOW STATEMENT | C2: FY-1 | D2: FY-2 | E2: FY-3
B3: BEGINNING CASH BALANCE | C3: 0 | D3: =C21 -> -144180.88 | E3: =D21 -> -162629.73
B4: CASH RECEIPTS | C4: =C5 -> 480126.41 | D4: =D5 -> 505074.21 | E4: =E5 -> 558719.79
B5: a. Sales Revenue | C5: ='Pro-Forma Income statement'!B10 -> 480126.41 | D5: ='Pro-Forma Income statement'!C10 -> 505074.21 | E5: ='Pro-Forma Income statement'!D10 -> 558719.79
B7: TOTAL CASH AVAILABLE | C7: =C3+C5 -> 480126.41 | D7: =D3+D5 -> 360893.32 | E7: =E3+E5 -> 396090.06
B8: CASH PAYMENTS
B9: VARIABLE EXPENSES | C9: ='Pro-Forma Income statement'!B11 -> 271693.18 | D9: ='Pro-Forma Income statement'!C11 -> 284721.44 | E9: ='Pro-Forma Income statement'!D11 -> 308937.91
B10: CORPORATE TAX | C10: ='Pro-Forma Income statement'!B26 -> -625 | D10: ='Pro-Forma Income statement'!C26 -> -1187.4997 | E10: ='Pro-Forma Income statement'!D26 -> 5053.833
B11: FIXED EXPENSES
B12: a.Rent | C12: ='Pro-Forma Income statement'!B14 -> 5000 | D12: ='Pro-Forma Income statement'!C14 -> 5000 | E12: ='Pro-Forma Income statement'!D14 -> 5000
B13: b.Employee Salaries | C13: ='Pro-Forma Income statement'!B15 -> 130000 | D13: ='Pro-Forma Income statement'!C15 -> 130000 | E13: ='Pro-Forma Income statement'!D15 -> 130000
B14: c. Utilities&Other | C14: ='Pro-Forma Income statement'!B16 -> 33500 | D14: ='Pro-Forma Income statement'!C16 -> 33500 | E14: ='Pro-Forma Income statement'!D16 -> 33500
B15: d. Marketing Costs | C15: ='Pro-Forma Income statement'!B17 -> 38000 | D15: ='Pro-Forma Income statement'!C17 -> 38000 | E15: ='Pro-Forma Income statement'!D17 -> 38000
B16: e.Loan Payments | C16: ='Pro-Forma Income statement'!B18 -> 19239.119 | D16: ='Pro-Forma Income statement'!C18 -> 19239.119 | E16: ='Pro-Forma Income statement'!D18 -> 19239.119
B17: f. Depreciation | C17: =VLOOKUP("Depreciation",PrFFY1,14,0) -> 7500 | D17: =VLOOKUP("Depreciation",PrFFY2,14,0) -> 14250 | E17: =VLOOKUP("Depreciation",PrFFY3,14,0) -> 12825
B18: Cash Flow From Investing Activities | C18: =-VLOOKUP("Private Investment",'36-Mo-Fin-Pr'!B1:C600,2,FALSE) -> -120000 | D18: 0 | E18: 0
B19: Cash flow from Financing Activities | C19: 0 | D19: 0 | E19: 0
B20: TOTAL CASH PAID OUT | C20: =SUM(C9:C17)-C18-C19 -> 624307.3 | D20: =SUM(D9:D17)-D18-D19 -> 523523.06 | E20: =SUM(E9:E17)-E18-E19 -> 552555.87
B21: ENDING CASH BALANCE | C21: =C7-C20 -> -144180.88 | D21: =D7-D20 -> -162629.73 | E21: =E7-E20 -> -156465.81

Sheet Financial Statement
A1: Balance Sheet
A2: As Of Dec. 31 FY-1
A3: Assets | B3: Dollars | D3: Liabilities and Owners' Equity | E3: Dollars
A4: Current assets: | D4: Current liabilities:
A5: Cash | B5: =VLOOKUP("Total Current Assets",AnFixcost,2,0) -> 50000 | D5: Accounts payable | E5: 0
A6: Accounts receivable | B6: 0 | D6: Current portion of long-term debt | E6: 0
A7: Inventory | B7: 0 | D7: Line of credit | E7: =B5 -> 50000
A8: Total Current Assets | B8: =SUM(B5:B7) -> 50000 | D8: Total Current Liabilities | E8: =SUM(E5:E7) -> 50000
A10: Fixed Assets: | D10: Owners' equity:
A11: Net Machinery and Equipment | B11: =VLOOKUP("private investment",AnFixcost,2,0) -> 120000 | D11: Private Investment | E11: =B11 -> 120000
D12: Total Owner's Equity | E12: =SUM(E11) -> 120000
A14: Total Assets | B14: =B8+B11 -> 170000 | D14: Total Liabilities And Owners Equity | E14: =E8+E12 -> 170000
A15: Income Statement
A16: For the Period Ended Dec. 31 FY-1
B17: Dollars
A18: Net sales (net of returns and allowances) | B18: ='Pro-Forma Income statement'!B10 -> 480126.41
A19: Less: Cost of sales | B19: ='Pro-Forma Income statement'!B11 -> 271693.18
A20: Operating income | B20: =B18-B19 -> 208433.23
A22: Operating Expenses:
A23: Salaries | B23: ='Pro-Forma CF'!C13 -> 130000
A24: Utilities | B24: ='Pro-Forma Income statement'!B16 -> 33500
A25: Marketing | B25: ='Pro-Forma CF'!C15 -> 38000
A26: Interest expense | B26: ='Pro-Forma CF'!C16 -> 19239.119 | D26: RECONCILEMENT OF NET WORTH OR EARNED SURPLUS
A27: Rent | B27: ='Pro-Forma CF'!C12 -> 5000 | D27: Net worth or earned surplus at the beginning of the period | E27: ='Pro-Forma CF'!C3 -> 0
A28: Other expenses | B28: ='Pro-Forma Income statement'!$B$19 -> 7500 | D28: Add: Net profit or Deduct: Loss | E28: ='Pro-Forma Income statement'!B27 -> -24180.884
A29: Total operating expenses | B29: =SUM(B23:B28) -> 233239.12 | D29: Total: | E29: =E27+E28 -> -24180.884
D30: Other Additions (Describe)
A31: Income before taxes | B31: =B20-B29 -> -24805.884 | D31: Total:
D32: Less: Withdrawals or Dividends
A33: Federal and other taxes (35%) | B33: ='Pro-Forma CF'!C10 -> -625 | D33: Other Deductions (Describe)
D34: Total Deductions:
A35: Net Income | B35: =B31-B33 -> -24180.884 | D35: Net Worth or Capital Funds on This Financial Statement
A36: Statement of Cash Flow
A37: For the Period Ended Dec. 31 FY-1
A39: Cash Flows for Operating Activities:
A40: Revenue | B40: ='Pro-Forma CF'!C5 -> 480126.41
A41: Add (deduct) items not affecting cash:
A42: Depreciation expense | B42: ='Pro-Forma CF'!C17 -> 7500
A43: Increase (decrease) in accounts receivable
A44: Increase (decrease) in inventory
...

Sheet Help Table
A2: 1 | B2: Income Statement
A3: 1.1 | B3: Depreciation
A4: 1.2 | B4: Insurance
A5: 1.3 | B5: Other Income
A6: 1.4 | B6: Other Expense
A7: 1.5 | B7: Tax Rate
A9: 2 | B9: Cash Flow Projection
A10: 2.1 | B10: Beginning CF
A11: 2.2 | B11: Receivables
A12: 2.3 | B12: Interest Income
A13: 2.4 | B13: Other Income
A14: 2.5 | B14: Insurance
... A25: 3.5 | B25: Detail of Inventory
